Workbook

Sheet Calcul rentabilité
A1: ADRESSE DU PROJET :
A2: INVESTISSEMENT
A3: Prix de vente (FAI)
A4: Taxe foncière (annuelle)
A5: Loyers HC (mensuel)
A6: Surface du projet (m2)
A7: Montant des charges de copro/mois
A8: Durée du crédit (année) | B8: 20
A9: Taux d'intérêt | B9: 0.0365

Sheet Ameublement
A1: GRILLE AMEUBLEMENT (compris livraison et montage)
A2: DESCRIPTIF | B2: T1 | C2: Nombre de T1 | D2: T2 | E2: Nombre de T2 | F2: T3 | G2: Nombre de T3 | H2: T4 | I2: Nombre de T4
A3: LLD | B3: 8200 | D3: 10200 | F3: 12200 | H3: 15200
A4: LCD Classique | B4: 10200 | D4: 12200 | F4: 14400 | H4: 17000
A5: LCD Thématique | B5: 19200 | D5: 22500 | F5: 25500 | H5: 29000
A6: TOTAL par type | C6: =C3*B3+C4*B4+C5*B5 -> 0 | E6: =E3*D3+E4*D4+E5*D5 -> 0 | G6: =G3*F3+G4*F4+G5*F5 -> 0 | I6: =I3*H3+I4*H4+I5*H5 -> 0
A7: TOTAL | B7: =C6+E6+G6+I6 -> 0

Sheet Budget travaux 1
A1: GRILLE TRAVAUX 1
A2: DESCRIPTIF | B2: T1 | C2: Nombre de T1 | D2: T2 | E2: Nombre de T2 | F2: T3 | G2: Nombre de T3 | H2: T4 | I2: Nombre de T4
A3: Rafraichissement | B3: 10000 | D3: 12500 | F3: 15000 | H3: 17500
A4: Rénovation | B4: 20000 | D4: 25000 | F4: 30000 | H4: 35000
A5: Création | B5: 30000 | D5: 40000 | F5: 50000 | H5: 60000
A6: TOTAL par type | C6: =C3*B3+C4*B4+C5*B5 -> 0 | E6: =E3*D3+E4*D4+E5*D5 -> 0 | G6: =G3*F3+G4*F4+G5*F5 -> 0 | I6: =I3*H3+I4*H4+I5*H5 -> 0
A7: Parties communes (Façade, couloirs, toitures)
A8: Travaux complémentaires
A9: TOTAL | B9: =C6+E6+G6+I6+B7+B8 -> 0

Sheet Budget travaux 2
A1: GRILLE TRAVAUX 2
A2: DESCRIPTIF | B2: Budget | C2: Nombre de lots concernés
A3: Plans à réaliser | B3: 500 | C3: =SUM('Budget travaux 1'!C3:C5,'Budget travaux 1'!E3:E5,'Budget travaux 1'!G3:G5,'Budget travaux 1'!I3:I5) -> 0
A4: Déclaration à prévoir (Si oui mettre 1) | B4: 1500
A5: Kit LCD classique (comprend serrures connectés, linges, mise en service et Budget revêtements muraux) | B5: 7000 | C5: =SUM(Ameublement!C4,Ameublement!E4,Ameublement!G4,Ameublement!I4) -> 0
A6: Kit LCD Thématique (comprend serrures connectés, linges, mise en service et Budget revêtements muraux) | B6: 10000 | C6: =SUM(Ameublement!C5,Ameublement!E5,Ameublement!G5,Ameublement!I5) -> 0
A7: TOTAL | C7: =C3*B3+C4*B4+C5*B5+C6*B6 -> 0

Sheet RÉCAPITULATIF (NE PAS MODIFIER)
A1: ADRESSE DU PROJET :
A2: INVESTISSEMENT
A3: Prix de vente | B3: ='Calcul rentabilité'!B3
A4: Frais de notaire | B4: =IF(B3>=100000,B3*7.5%,B3*10%) -> 0
A5: Travaux | B5: ='Budget travaux 1'!B9+'Budget travaux 2'!C7 -> 0
A6: Ameublement | B6: =Ameublement!B7 -> 0
A7: TOTAL DE L'INVESTISSEMENT | B7: =SUM(B3:B6) -> 0
A9: Taxe foncière | B9: ='Calcul rentabilité'!B4
A10: Loyers HC (mensuel) | B10: ='Calcul rentabilité'!B5
A11: Loyers HC (annuel) | B11: 0
A13: Assurance PNO
A14: Surface (m2) | B14: ='Calcul rentabilité'!B6
A15: Taux d'assurance (Prix au m2) | B15: 2
A16: Montant de l'Assurance PNO | B16: =B15*B14 -> 0
A18: Gestion locative
A19: Coût gestion loc | B19: 0.08
A20: Montant de gestion/an | B20: =B19*B11 -> 0
A22: Gestion comptable
A23: Prix de gestion/an | B23: 600
A25: Charges de copropriété
A26: Montant des charges/mois | B26: ='Calcul rentabilité'!B7
A27: Montant des charges/an | B27: =B26*12 -> 0
A29: Crédit
A30: Demande de financement : https://www.immobilierclub.com/courtage-en-financement
A31: Apport (Frais de notaire de base ) | B31: =B4 -> 0
A32: Montant du prêt | B32: =B7-B31 -> 0
A33: Durée (année) | B33: ='Calcul rentabilité'!B8 -> 20
A34: Taux d'intérêt | B34: ='Calcul rentabilité'!B9 -> 0.0365
A35: Taux d'assurance | B35: 0.0034
A36: Mensualité | B36: =ROUNDUP((PMT((1+B34)^(1/12)-1,B33*12,B32)*-1)+(B35*B32)/12,0) -> 0
A37: Mensualité à l'année | B37: =B36*12 -> 0
A38: Intérêts total du crédit | B38: =B37*B33-B32 -> 0
A39: Intérêts/AN | B39: =B38/B33 -> 0
A41: Cash-flow avant impôt
A42: Cash flow avant impôt/an | B42: =B11-B9-B16-B20-B23-B27-B37 -> -600
A43: Cash flow avant impôt/mois | B43: =B42/12 -> -50
A45: Amortissement
A46: Type | B46: Nombre d'année | C46: Montant amortissable/an
A47: Bati | B47: 25 | C47: =(B3*80%)/B47 -> 0
A48: Travaux | B48: 15 | C48: =B5/B48 -> 0
...
