Workbook

Sheet Compte de résultats
B2: Emeline SIRON | G2: ANNÉE : | H2: 2025
B3: Compte de résultats
B5: CASH-FLOW | C5: Actuel | F5: Objectif | G5: Delta
C6: Lui | D6: Elle | E6: Foyer | F6: Goal | G6: ∆
B8: Total Revenus | C8: =C38 | D8: =D38 | E8: =E38 | F8: =F38 | G8: =E8-F8
B9: Total Dépenses | C9: =C122 | D9: =D122 | E9: =E122 | F9: =F122 | G9: =E9-F9
B11: TOTAL CASH-FLOW MENSUEL | C11: =C8-C9 | D11: =D8-D9 | E11: =E8-E9 | F11: =F8-F9 | G11: =E11-F11
B12: TOTAL CASH-FLOW ANNUEL | C12: =C11*12 | D12: =D11*12 | E12: =E11*12 | F12: =F11*12 | G12: =E12-F12
B15: REVENUS MENSUELS | C15: Actuel | F15: Objectif | G15: Delta | H15: Pourcentage
C16: Lui | D16: Elle | E16: Foyer | F16: Goal | G16: ∆
B17: ACTIFS
B18: Travail : Salaire | C18: 1500 | D18: 1200 | E18: =C18+D18 | F18: 6000 | G18: =E18-F18
B19: Travail : Prime | C19: 100 | E19: =C19+D19 | G19: =E19-F19
B20: Travail : Commission | D20: 100 | E20: =C20+D20 | G20: =E20-F20
B21: Travail : Bonus | C21: 50 | E21: =C21+D21 | G21: =E21-F21
B22: Travail : Dividende | D22: 50 | E22: =C22+D22 | G22: =E22-F22
B23: Travail : Micro-entrepreneur | C23: 150 | E23: =C23+D23 | G23: =E23-F23
B24: Autres sources | C24: 25 | E24: =C24+D24 | G24: =E24-F24
B25: TOTAL DES REVENUS ACTIFS | C25: =SUM(C18:C24) | D25: =SUM(D18:D24) | E25: =C25+D25 | F25: =SUM(F18:F24) | G25: =E25-F25 | H25: =PRODUCT(E25,1)/$E$38
B27: PASSIFS
B28: Immobilier : Loyers | C28: 1000 | E28: =C28+D28 | F28: 6000 | G28: =E28-F28
B29: Immobilier : Dividendes | D29: 500 | E29: =C29+D29 | G29: =E29-F29
B30: Bourse : Dividendes | C30: 550 | E30: =C30+D30 | G30: =E30-F30
B31: Bourse : Trading | D31: 650 | E31: =C31+D31 | G31: =E31-F31
B32: Private Equity | C32: 350 | D32: 300 | E32: =C32+D32 | G32: =E32-F32
B33: Crowdfunding | C33: 150 | D33: 250 | E33: =C33+D33 | G33: =E33-F33
B34: Autres sources | D34: 150 | E34: =C34+D34 | G34: =E34-F34
B35: TOTAL DES REVENUS PASSIFS | C35: =SUM(C28:C34) | D35: =SUM(D28:D34) | E35: =C35+D35 | F35: =SUM(F28:F34) | G35: =E35-F35 | H35: =PRODUCT(E35,1)/$E$38
B38: TOTAL REVENUS MENSUELS | C38: =C25+C35 | D38: =D25+D35 | E38: =E25+E35 | F38: =F25+F35 | G38: =E38-F38
B39: TOTAL REVENUS ANNUELS | C39: =C38*12 | D39: =D38*12 | E39: =E38*12 | F39: =F38*12 | G39: =E39-F39
B42: ÉPARGNE MENSUELLE | C42: Actuel | F42: Objectif | G42: Delta | H42: Pourcentage
C43: Lui | D43: Elle | E43: Foyer | F43: Goal | G43: ∆
B44: NON NÉGOCIABLE
B45: Épargne | C45: 1000 | D45: 2500 | E45: =C45+D45 | F45: 5500 | G45: =E45-F45
B46: TOTAL DE L'ÉPARGNE | C46: =SUM(C45) | D46: =SUM(D45) | E46: =C46+D46 | F46: =SUM(F45) | G46: =E46-F46 | H46: =PRODUCT(E46,1)/$E$38
B49: TOTAL ÉPARGNE MENSUELLE | C49: =C46 | D49: =D46 | E49: =E46 | F49: =F46 | G49: =E49-F49
B50: TOTAL ÉPARGNE ANNUELLE | C50: =PRODUCT(C49,12) | D50: =PRODUCT(D49,12) | E50: =PRODUCT(E49,12) | F50: =PRODUCT(F49,12) | G50: =E50-F50
B53: DÉPENSES MENSUELLES | C53: Actuel | F53: Objectif | G53: Delta | H53: Pourcentage
C54: Lui | D54: Elle | E54: Foyer | F54: Goal | G54: ∆
B55: SURVIE
...

Sheet Bilan
B2: Emeline SIRON | G2: ANNÉE : | H2: 2025
B3: Bilan
B5: PATRIMOINE | C5: Actuel | F5: Objectif | G5: Delta
C6: Lui | D6: Elle | E6: Foyer | F6: Goal | G6: ∆
B8: Total Actif | C8: =C103 | D8: =D103 | E8: =E103 | F8: =F103 | G8: =G103
B9: Total Passif | C9: =C130 | D9: =D130 | E9: =E130 | F9: =F130 | G9: =G130
B11: TOTAL PATRIMOINE NET | C11: =C8-C9 | D11: =D8-D9 | E11: =E8-E9 | F11: =F8-F9 | G11: =E11-F11
B14: ACTIF | C14: Actuel | F14: Objectif | G14: Delta | H14: Pourcentage
C15: Lui | D15: Elle | E15: Foyer | F15: Goal | G15: ∆
B16: LIQUIDITÉ
B17: Compte courant | C17: 300000 | E17: =C17+D17 | F17: 550000 | G17: =E17-F17
B18: Livret A | E18: =C18+D18 | G18: =E18-F18
B19: LDDS | E19: =C19+D19 | G19: =E19-F19
B20: LEP | E20: =C20+D20 | G20: =E20-F20
B21: Livret Jeune | E21: =C21+D21 | G21: =E21-F21
B22: CEL | E22: =C22+D22 | G22: =E22-F22
B23: PEL | E23: =C23+D23 | G23: =E23-F23
B24: PERP | E24: =C24+D24 | G24: =E24-F24
B25: Compte à terme CAT | E25: =C25+D25 | G25: =E25-F25
B26: Compte Sur Livret CSL | E26: =C26+D26 | G26: =E26-F26
B27: Autre | E27: =C27+D27 | G27: =E27-F27
B28: TOTAL LIQUIDITÉ | C28: =SUM(C17:C27) | D28: =SUM(D17:D27) | E28: =C28+D28 | F28: =SUM(F17:F27) | G28: =E28-F28 | H28: =PRODUCT(E28,1)/$E$103
B30: IMMOBILIER
B31: Terrain | C31: 400000 | E31: =C31+D31 | G31: =E31-F31
B32: Appartement | E32: =C32+D32 | G32: =E32-F32
B33: Immeuble | E33: =C33+D33 | G33: =E33-F33
B34: Maison | E34: =C34+D34 | G34: =E34-F34
B35: Commerce | E35: =C35+D35 | G35: =E35-F35
B36: Bureau | E36: =C36+D36 | G36: =E36-F36
B37: Entrepôt | E37: =C37+D37 | G37: =E37-F37
B38: Parking | E38: =C38+D38 | G38: =E38-F38
B39: Cave | E39: =C39+D39 | G39: =E39-F39
B40: Autre | E40: =C40+D40 | G40: =E40-F40
B41: TOTAL IMMOBILIER | C41: =SUM(C31:C40) | D41: =SUM(D31:D40) | E41: =C41+D41 | F41: =SUM(F31:F40) | G41: =E41-F41 | H41: =PRODUCT(E41,1)/$E$103
B43: BOURSE
B44: Action | C44: 250000 | E44: =C44+D44 | F44: 225000 | G44: =E44-F44
B45: Obligation | E45: =C45+D45 | G45: =E45-F45
B46: ETF | E46: =C46+D46 | G46: =E46-F46
B47: SICAV | E47: =C47+D47 | G47: =E47-F47
B48: FCP | E48: =C48+D48 | G48: =E48-F48
...

Sheet Croissance
C2: Croissance
B5: ÉVOLUTION AU COURS DES ANNÉES | C5: ÉVOLUTION AU COURS DES ANNÉES
C7: Année | D7: Revenus actifs | E7: Revenus passifs | F7: Total des revenus | H7: Liquidité | I7: Immobilier | J7: Bourse | K7: Cryptomonnaie | L7: Private Equity | M7: Autre | N7: Patrimoine brut | P7: Patrimoine net
C8: A-4 | D8: 1500 | E8: 5000 | F8: =E8+D8 | H8: 50000 | N8: =SUM(H8:M8)
C9: A-3 | D9: 3000 | E9: 10000 | F9: =E9+D9 | H9: 100000 | N9: =SUM(H9:M9)
C10: A-2 | D10: 11000 | E10: 15000 | F10: =E10+D10 | H10: 200000 | N10: =SUM(H10:M10)
C11: A-1 | D11: 25000 | E11: 25000 | F11: =E11+D11 | H11: 250000 | N11: =SUM(H11:M11)
C12: En cours | D12: =PRODUCT('Compte de résultats'!E25,12) | E12: =PRODUCT('Compte de résultats'!E35,12) | F12: =E12+D12 | H12: =Bilan!E28 | I12: =Bilan!E41 | J12: =Bilan!E55 | K12: =Bilan!E66 | L12: =Bilan!E74 | M12: =Bilan!E81+Bilan!E92+Bilan!E100 | N12: =SUM(H12:M12) | P12: =Bilan!E11
C17: CROISSANCE DES REVENUS | J17: CROISSANCE DU PATRIMOINE BRUT
C46: CROISSANCE DU PATRIMOINE NET

Sheet Objectifs
B2: Objectifs
B5: ACTIONS | C5: STATUS
B6: Générer un SMIC mensuel de revenus passifs | C6: À faire
B7: Générer 2 500 € mensuel de revenus passifs | C7: À faire
B8: Générer 5 000 € mensuel de revenus passifs | C8: En cours
B9: Générer 10 000 € mensuel de revenus passifs | C9: À faire
B10: Générer un SMIC mensuel de cash-flow net avec l'immobilier | C10: Fait
B11: Générer 2 500 € mensuel de cash-flow net avec l'immobilier | C11: À faire
B12: Générer 5 000 € mensuel de cash-flow net avec l'immobilier | C12: À faire
B13: Générer 100 € mensuel de dividendes | C13: Fait
B14: Générer 500 € mensuel de dividendes | C14: À faire
B15: Générer 2 000 € mensuel de dividendes | C15: À faire
B16: Générer 100 € mensuel avec le trading | C16: À faire
... B38: Détenir 5 000 000 € de patrimoine net | C38: À faire

Sheet Graphiques
B2: À NE PAS TOUCHER !
B5: Graphiques

Sheet Pivots
B2: À NE PAS TOUCHER !
C4: Revenus
C5: Autre | D5: ='Compte de résultats'!E24+'Compte de résultats'!E34
C6: Crowdfunding | D6: ='Compte de résultats'!E33
C7: Private Equity | D7: ='Compte de résultats'!E32
C8: Bourse | D8: =SUM('Compte de résultats'!E30:E31)
C9: Immobilier | D9: =SUM('Compte de résultats'!E28:E29)
C10: Travail | D10: =SUM('Compte de résultats'!E18:E23)
E12: Dépenses
E13: Autre | F13: ='Compte de résultats'!E122-F18-F17-F16-F15-F14
E14: Plaisir | F14: =SUM('Compte de résultats'!E98:E106)+'Compte de résultats'!E111+'Compte de résultats'!E112+'Compte de résultats'!E113+'Compte de résultats'!E116
E15: Voiture | F15: =SUM('Compte de résultats'!E91:E93)
E16: Alimentation | F16: ='Compte de résultats'!E56
E17: Invest. locatif | F17: =SUM('Compte de résultats'!E76:E86)
E18: Rési. princip. | F18: =SUM('Compte de résultats'!E59:E65)+SUM('Compte de résultats'!E73:E75)
G20: Épargne VS Dépenses
G21: Épargne | H21: Dépenses
G22: ='Compte de résultats'!E49 | H22: ='Compte de résultats'!E122
I24: Dépenses par catégorie
I25: Autre | J25: =F13/SUM($F$13:$F$18)
I26: Plaisir | J26: =F14/SUM($F$13:$F$18)
I27: Voiture | J27: =F15/SUM($F$13:$F$18)
I28: Alimentation | J28: =F16/SUM($F$13:$F$18)
I29: Invest. locatif | J29: =F17/SUM($F$13:$F$18)
I30: Rési. princip. | J30: =F18/SUM($F$13:$F$18)
K32: Taux d'épargne
K33: Épargne | L33: Objectif
K34: ='Compte de résultats'!H46
M36: Patrimoine
M37: Brut | N37: Net
M38: =Bilan!E103 | N38: =Bilan!E11
O42: Objectif revenus
O43: Actuel | P43: Objectif
O44: ='Compte de résultats'!E39 | P44: ='Compte de résultats'!F39
Q48: Objectif patrimoine net
Q49: Actuel | R49: Objectif
Q50: =Bilan!E11 | R50: =Bilan!F11
S54: Objectif revenus reste
S55: Actuel | T55: Objectif
S56: =O44 | T56: =P44-O44
...
