Workbook

Sheet Simulateur Amortissement
A1: SIMULATEUR TABLEAU D'AMORTISSEMENT
A2: La méthode Emeline SIRON — Cases jaunes = à modifier | Cases vertes = résultats automatiques
A4: PARAMÈTRES DU CRÉDIT
A5: Montant emprunté | B5: 200000
A6: Taux d'intérêt annuel | B6: 0.035
A7: Durée (années) | B7: 20
A8: Taux assurance annuel | B8: 0.003
A9: Différé (mois) | B9: 0
A11: RÉSULTATS SYNTHÈSE
A12: Mensualité crédit (hors assurance) | B12: =-PMT(B6/12,B7*12,B5)
A13: Mensualité assurance | B13: =B5*B8/12
A14: MENSUALITÉ TOTALE | B14: =B12+B13
A15: Total intérêts payés | B15: =B12*B7*12-B5
A16: Total assurance payée | B16: =B13*B7*12
A17: COÛT TOTAL DU CRÉDIT | B17: =B15+B16
A18: Coût total de l'opération | B18: =B5+B17

Sheet Tableau Amortissement
A1: TABLEAU D'AMORTISSEMENT DÉTAILLÉ
A3: Mois | B3: Mensualité | C3: Intérêts | D3: Capital amorti | E3: Assurance | F3: Total payé | G3: Capital restant dû
A4: 1 | B4: =IF(A4>'Simulateur Amortissement'!B7*12,"",'Simulateur Amortissement'!B12) | C4: ='Simulateur Amortissement'!B5*'Simulateur Amortissement'!B6/12 | D4: =IF(B4="","",B4-C4) | E4: =IF(A4>'Simulateur Amortissement'!B7*12,"",'Simulateur Amortissement'!B13) | F4: =IF(B4="","",B4+E4) | G4: ='Simulateur Amortissement'!B5-D4
A5: 2 | B5: =IF(A5>'Simulateur Amortissement'!B7*12,"",'Simulateur Amortissement'!B12) | C5: =G4*'Simulateur Amortissement'!B6/12 | D5: =IF(B5="","",B5-C5) | E5: =IF(A5>'Simulateur Amortissement'!B7*12,"",'Simulateur Amortissement'!B13) | F5: =IF(B5="","",B5+E5) | G5: =G4-D5
A6: 3 | B6: =IF(A6>'Simulateur Amortissement'!B7*12,"",'Simulateur Amortissement'!B12) | C6: =G5*'Simulateur Amortissement'!B6/12 | D6: =IF(B6="","",B6-C6) | E6: =IF(A6>'Simulateur Amortissement'!B7*12,"",'Simulateur Amortissement'!B13) | F6: =IF(B6="","",B6+E6) | G6: =G5-D6
A7: 4 | B7: =IF(A7>'Simulateur Amortissement'!B7*12,"",'Simulateur Amortissement'!B12) | C7: =G6*'Simulateur Amortissement'!B6/12 | D7: =IF(B7="","",B7-C7) | E7: =IF(A7>'Simulateur Amortissement'!B7*12,"",'Simulateur Amortissement'!B13) | F7: =IF(B7="","",B7+E7) | G7: =G6-D7
A8: 5 | B8: =IF(A8>'Simulateur Amortissement'!B7*12,"",'Simulateur Amortissement'!B12) | C8: =G7*'Simulateur Amortissement'!B6/12 | D8: =IF(B8="","",B8-C8) | E8: =IF(A8>'Simulateur Amortissement'!B7*12,"",'Simulateur Amortissement'!B13) | F8: =IF(B8="","",B8+E8) | G8: =G7-D8
A9: 6 | B9: =IF(A9>'Simulateur Amortissement'!B7*12,"",'Simulateur Amortissement'!B12) | C9: =G8*'Simulateur Amortissement'!B6/12 | D9: =IF(B9="","",B9-C9) | E9: =IF(A9>'Simulateur Amortissement'!B7*12,"",'Simulateur Amortissement'!B13) | F9: =IF(B9="","",B9+E9) | G9: =G8-D9
A10: 7 | B10: =IF(A10>'Simulateur Amortissement'!B7*12,"",'Simulateur Amortissement'!B12) | C10: =G9*'Simulateur Amortissement'!B6/12 | D10: =IF(B10="","",B10-C10) | E10: =IF(A10>'Simulateur Amortissement'!B7*12,"",'Simulateur Amortissement'!B13) | F10: =IF(B10="","",B10+E10) | G10: =G9-D10
A11: 8 | B11: =IF(A11>'Simulateur Amortissement'!B7*12,"",'Simulateur Amortissement'!B12) | C11: =G10*'Simulateur Amortissement'!B6/12 | D11: =IF(B11="","",B11-C11) | E11: =IF(A11>'Simulateur Amortissement'!B7*12,"",'Simulateur Amortissement'!B13) | F11: =IF(B11="","",B11+E11) | G11: =G10-D11
A12: 9 | B12: =IF(A12>'Simulateur Amortissement'!B7*12,"",'Simulateur Amortissement'!B12) | C12: =G11*'Simulateur Amortissement'!B6/12 | D12: =IF(B12="","",B12-C12) | E12: =IF(A12>'Simulateur Amortissement'!B7*12,"",'Simulateur Amortissement'!B13) | F12: =IF(B12="","",B12+E12) | G12: =G11-D12
A13: 10 | B13: =IF(A13>'Simulateur Amortissement'!B7*12,"",'Simulateur Amortissement'!B12) | C13: =G12*'Simulateur Amortissement'!B6/12 | D13: =IF(B13="","",B13-C13) | E13: =IF(A13>'Simulateur Amortissement'!B7*12,"",'Simulateur Amortissement'!B13) | F13: =IF(B13="","",B13+E13) | G13: =G12-D13
A14: 11 | B14: =IF(A14>'Simulateur Amortissement'!B7*12,"",'Simulateur Amortissement'!B12) | C14: =G13*'Simulateur Amortissement'!B6/12 | D14: =IF(B14="","",B14-C14) | E14: =IF(A14>'Simulateur Amortissement'!B7*12,"",'Simulateur Amortissement'!B13) | F14: =IF(B14="","",B14+E14) | G14: =G13-D14
A15: 12 | B15: =IF(A15>'Simulateur Amortissement'!B7*12,"",'Simulateur Amortissement'!B12) | C15: =G14*'Simulateur Amortissement'!B6/12 | D15: =IF(B15="","",B15-C15) | E15: =IF(A15>'Simulateur Amortissement'!B7*12,"",'Simulateur Amortissement'!B13) | F15: =IF(B15="","",B15+E15) | G15: =G14-D15
A16: 13 | B16: =IF(A16>'Simulateur Amortissement'!B7*12,"",'Simulateur Amortissement'!B12) | C16: =G15*'Simulateur Amortissement'!B6/12 | D16: =IF(B16="","",B16-C16) | E16: =IF(A16>'Simulateur Amortissement'!B7*12,"",'Simulateur Amortissement'!B13) | F16: =IF(B16="","",B16+E16) | G16: =G15-D16
A17: 14 | B17: =IF(A17>'Simulateur Amortissement'!B7*12,"",'Simulateur Amortissement'!B12) | C17: =G16*'Simulateur Amortissement'!B6/12 | D17: =IF(B17="","",B17-C17) | E17: =IF(A17>'Simulateur Amortissement'!B7*12,"",'Simulateur Amortissement'!B13) | F17: =IF(B17="","",B17+E17) | G17: =G16-D17
A18: 15 | B18: =IF(A18>'Simulateur Amortissement'!B7*12,"",'Simulateur Amortissement'!B12) | C18: =G17*'Simulateur Amortissement'!B6/12 | D18: =IF(B18="","",B18-C18) | E18: =IF(A18>'Simulateur Amortissement'!B7*12,"",'Simulateur Amortissement'!B13) | F18: =IF(B18="","",B18+E18) | G18: =G17-D18
A19: 16 | B19: =IF(A19>'Simulateur Amortissement'!B7*12,"",'Simulateur Amortissement'!B12) | C19: =G18*'Simulateur Amortissement'!B6/12 | D19: =IF(B19="","",B19-C19) | E19: =IF(A19>'Simulateur Amortissement'!B7*12,"",'Simulateur Amortissement'!B13) | F19: =IF(B19="","",B19+E19) | G19: =G18-D19
A20: 17 | B20: =IF(A20>'Simulateur Amortissement'!B7*12,"",'Simulateur Amortissement'!B12) | C20: =G19*'Simulateur Amortissement'!B6/12 | D20: =IF(B20="","",B20-C20) | E20: =IF(A20>'Simulateur Amortissement'!B7*12,"",'Simulateur Amortissement'!B13) | F20: =IF(B20="","",B20+E20) | G20: =G19-D20
A21: 18 | B21: =IF(A21>'Simulateur Amortissement'!B7*12,"",'Simulateur Amortissement'!B12) | C21: =G20*'Simulateur Amortissement'!B6/12 | D21: =IF(B21="","",B21-C21) | E21: =IF(A21>'Simulateur Amortissement'!B7*12,"",'Simulateur Amortissement'!B13) | F21: =IF(B21="","",B21+E21) | G21: =G20-D21
A22: 19 | B22: =IF(A22>'Simulateur Amortissement'!B7*12,"",'Simulateur Amortissement'!B12) | C22: =G21*'Simulateur Amortissement'!B6/12 | D22: =IF(B22="","",B22-C22) | E22: =IF(A22>'Simulateur Amortissement'!B7*12,"",'Simulateur Amortissement'!B13) | F22: =IF(B22="","",B22+E22) | G22: =G21-D22
A23: 20 | B23: =IF(A23>'Simulateur Amortissement'!B7*12,"",'Simulateur Amortissement'!B12) | C23: =G22*'Simulateur Amortissement'!B6/12 | D23: =IF(B23="","",B23-C23) | E23: =IF(A23>'Simulateur Amortissement'!B7*12,"",'Simulateur Amortissement'!B13) | F23: =IF(B23="","",B23+E23) | G23: =G22-D23
A24: 21 | B24: =IF(A24>'Simulateur Amortissement'!B7*12,"",'Simulateur Amortissement'!B12) | C24: =G23*'Simulateur Amortissement'!B6/12 | D24: =IF(B24="","",B24-C24) | E24: =IF(A24>'Simulateur Amortissement'!B7*12,"",'Simulateur Amortissement'!B13) | F24: =IF(B24="","",B24+E24) | G24: =G23-D24
A25: 22 | B25: =IF(A25>'Simulateur Amortissement'!B7*12,"",'Simulateur Amortissement'!B12) | C25: =G24*'Simulateur Amortissement'!B6/12 | D25: =IF(B25="","",B25-C25) | E25: =IF(A25>'Simulateur Amortissement'!B7*12,"",'Simulateur Amortissement'!B13) | F25: =IF(B25="","",B25+E25) | G25: =G24-D25
A26: 23 | B26: =IF(A26>'Simulateur Amortissement'!B7*12,"",'Simulateur Amortissement'!B12) | C26: =G25*'Simulateur Amortissement'!B6/12 | D26: =IF(B26="","",B26-C26) | E26: =IF(A26>'Simulateur Amortissement'!B7*12,"",'Simulateur Amortissement'!B13) | F26: =IF(B26="","",B26+E26) | G26: =G25-D26
A27: 24 | B27: =IF(A27>'Simulateur Amortissement'!B7*12,"",'Simulateur Amortissement'!B12) | C27: =G26*'Simulateur Amortissement'!B6/12 | D27: =IF(B27="","",B27-C27) | E27: =IF(A27>'Simulateur Amortissement'!B7*12,"",'Simulateur Amortissement'!B13) | F27: =IF(B27="","",B27+E27) | G27: =G26-D27
A28: 25 | B28: =IF(A28>'Simulateur Amortissement'!B7*12,"",'Simulateur Amortissement'!B12) | C28: =G27*'Simulateur Amortissement'!B6/12 | D28: =IF(B28="","",B28-C28) | E28: =IF(A28>'Simulateur Amortissement'!B7*12,"",'Simulateur Amortissement'!B13) | F28: =IF(B28="","",B28+E28) | G28: =G27-D28
A29: 26 | B29: =IF(A29>'Simulateur Amortissement'!B7*12,"",'Simulateur Amortissement'!B12) | C29: =G28*'Simulateur Amortissement'!B6/12 | D29: =IF(B29="","",B29-C29) | E29: =IF(A29>'Simulateur Amortissement'!B7*12,"",'Simulateur Amortissement'!B13) | F29: =IF(B29="","",B29+E29) | G29: =G28-D29
A30: 27 | B30: =IF(A30>'Simulateur Amortissement'!B7*12,"",'Simulateur Amortissement'!B12) | C30: =G29*'Simulateur Amortissement'!B6/12 | D30: =IF(B30="","",B30-C30) | E30: =IF(A30>'Simulateur Amortissement'!B7*12,"",'Simulateur Amortissement'!B13) | F30: =IF(B30="","",B30+E30) | G30: =G29-D30
A31: 28 | B31: =IF(A31>'Simulateur Amortissement'!B7*12,"",'Simulateur Amortissement'!B12) | C31: =G30*'Simulateur Amortissement'!B6/12 | D31: =IF(B31="","",B31-C31) | E31: =IF(A31>'Simulateur Amortissement'!B7*12,"",'Simulateur Amortissement'!B13) | F31: =IF(B31="","",B31+E31) | G31: =G30-D31
A32: 29 | B32: =IF(A32>'Simulateur Amortissement'!B7*12,"",'Simulateur Amortissement'!B12) | C32: =G31*'Simulateur Amortissement'!B6/12 | D32: =IF(B32="","",B32-C32) | E32: =IF(A32>'Simulateur Amortissement'!B7*12,"",'Simulateur Amortissement'!B13) | F32: =IF(B32="","",B32+E32) | G32: =G31-D32
A33: 30 | B33: =IF(A33>'Simulateur Amortissement'!B7*12,"",'Simulateur Amortissement'!B12) | C33: =G32*'Simulateur Amortissement'!B6/12 | D33: =IF(B33="","",B33-C33) | E33: =IF(A33>'Simulateur Amortissement'!B7*12,"",'Simulateur Amortissement'!B13) | F33: =IF(B33="","",B33+E33) | G33: =G32-D33
A34: 31 | B34: =IF(A34>'Simulateur Amortissement'!B7*12,"",'Simulateur Amortissement'!B12) | C34: =G33*'Simulateur Amortissement'!B6/12 | D34: =IF(B34="","",B34-C34) | E34: =IF(A34>'Simulateur Amortissement'!B7*12,"",'Simulateur Amortissement'!B13) | F34: =IF(B34="","",B34+E34) | G34: =G33-D34
A35: 32 | B35: =IF(A35>'Simulateur Amortissement'!B7*12,"",'Simulateur Amortissement'!B12) | C35: =G34*'Simulateur Amortissement'!B6/12 | D35: =IF(B35="","",B35-C35) | E35: =IF(A35>'Simulateur Amortissement'!B7*12,"",'Simulateur Amortissement'!B13) | F35: =IF(B35="","",B35+E35) | G35: =G34-D35
A36: 33 | B36: =IF(A36>'Simulateur Amortissement'!B7*12,"",'Simulateur Amortissement'!B12) | C36: =G35*'Simulateur Amortissement'!B6/12 | D36: =IF(B36="","",B36-C36) | E36: =IF(A36>'Simulateur Amortissement'!B7*12,"",'Simulateur Amortissement'!B13) | F36: =IF(B36="","",B36+E36) | G36: =G35-D36
A37: 34 | B37: =IF(A37>'Simulateur Amortissement'!B7*12,"",'Simulateur Amortissement'!B12) | C37: =G36*'Simulateur Amortissement'!B6/12 | D37: =IF(B37="","",B37-C37) | E37: =IF(A37>'Simulateur Amortissement'!B7*12,"",'Simulateur Amortissement'!B13) | F37: =IF(B37="","",B37+E37) | G37: =G36-D37
A38: 35 | B38: =IF(A38>'Simulateur Amortissement'!B7*12,"",'Simulateur Amortissement'!B12) | C38: =G37*'Simulateur Amortissement'!B6/12 | D38: =IF(B38="","",B38-C38) | E38: =IF(A38>'Simulateur Amortissement'!B7*12,"",'Simulateur Amortissement'!B13) | F38: =IF(B38="","",B38+E38) | G38: =G37-D38
A39: 36 | B39: =IF(A39>'Simulateur Amortissement'!B7*12,"",'Simulateur Amortissement'!B12) | C39: =G38*'Simulateur Amortissement'!B6/12 | D39: =IF(B39="","",B39-C39) | E39: =IF(A39>'Simulateur Amortissement'!B7*12,"",'Simulateur Amortissement'!B13) | F39: =IF(B39="","",B39+E39) | G39: =G38-D39
A40: 37 | B40: =IF(A40>'Simulateur Amortissement'!B7*12,"",'Simulateur Amortissement'!B12) | C40: =G39*'Simulateur Amortissement'!B6/12 | D40: =IF(B40="","",B40-C40) | E40: =IF(A40>'Simulateur Amortissement'!B7*12,"",'Simulateur Amortissement'!B13) | F40: =IF(B40="","",B40+E40) | G40: =G39-D40
A41: 38 | B41: =IF(A41>'Simulateur Amortissement'!B7*12,"",'Simulateur Amortissement'!B12) | C41: =G40*'Simulateur Amortissement'!B6/12 | D41: =IF(B41="","",B41-C41) | E41: =IF(A41>'Simulateur Amortissement'!B7*12,"",'Simulateur Amortissement'!B13) | F41: =IF(B41="","",B41+E41) | G41: =G40-D41
...

Sheet Comparateur Durées
A1: COMPARATEUR DE DURÉES DE CRÉDIT
B3: 10 ans | C3: 15 ans | D3: 20 ans | E3: 25 ans
A4: Nombre de mensualités | B4: =10*12 | C4: =15*12 | D4: =20*12 | E4: =25*12
A5: Mensualité (hors assurance) | B5: =-PMT('Simulateur Amortissement'!B6/12,10*12,'Simulateur Amortissement'!B5) | C5: =-PMT('Simulateur Amortissement'!B6/12,15*12,'Simulateur Amortissement'!B5) | D5: =-PMT('Simulateur Amortissement'!B6/12,20*12,'Simulateur Amortissement'!B5) | E5: =-PMT('Simulateur Amortissement'!B6/12,25*12,'Simulateur Amortissement'!B5)
A6: Mensualité assurance | B6: ='Simulateur Amortissement'!B13 | C6: ='Simulateur Amortissement'!B13 | D6: ='Simulateur Amortissement'!B13 | E6: ='Simulateur Amortissement'!B13
A7: Mensualité totale | B7: =B5+B6 | C7: =C5+C6 | D7: =D5+D6 | E7: =E5+E6
A8: Total intérêts | B8: =-PMT('Simulateur Amortissement'!B6/12,10*12,'Simulateur Amortissement'!B5)*10*12-'Simulateur Amortissement'!B5 | C8: =-PMT('Simulateur Amortissement'!B6/12,15*12,'Simulateur Amortissement'!B5)*15*12-'Simulateur Amortissement'!B5 | D8: =-PMT('Simulateur Amortissement'!B6/12,20*12,'Simulateur Amortissement'!B5)*20*12-'Simulateur Amortissement'!B5 | E8: =-PMT('Simulateur Amortissement'!B6/12,25*12,'Simulateur Amortissement'!B5)*25*12-'Simulateur Amortissement'!B5
A9: Total assurance | B9: ='Simulateur Amortissement'!B13*10*12 | C9: ='Simulateur Amortissement'!B13*15*12 | D9: ='Simulateur Amortissement'!B13*20*12 | E9: ='Simulateur Amortissement'!B13*25*12
A10: Coût total du crédit | B10: =B8+B9 | C10: =C8+C9 | D10: =D8+D9 | E10: =E8+E9
A12: 💡 ANALYSE :
A13: Plus la durée est longue, plus la mensualité est basse (meilleur cashflow) mais plus le coût total est élevé. L'investisseur immobilier privilégie souvent 20-25 ans pour maximiser le cashflow et utiliser l'effet de levier. L'argent économisé sur les mensualités peut être réinvesti dans un nouveau bien.
